<?xml version="1.0"?>
<robot name="Wheatley">
	<material name="metal">
		<color rgba="0.58 0.58 0.58 1"/>
	</material>
	
	<material name="rubber">
		<color rgba="0 0 0 1"/>
	</material>
	
	<material name="camera">
		<color rgba="0 0 0 1"/>
	</material>
	
	
	<!-- parts -->
	<link name="robot">
		<visual>
			<origin xyz="0 0 0.06"/>
			<geometry>
				<cylinder length="0.08" radius="0.1125"/>
			</geometry>
			<material name="metal"/>
		</visual>
		<visual>
			<origin xyz="0 0 0.17"/>
			<geometry>
				<box size="0.075 0.165 0.155"/>
			</geometry>
			<material name="metal"/>
		</visual>
	</link>

	<link name="camera_link">
		<visual>
			<origin xyz="0 -0.05 0.02"/>
			<geometry>
				<box size="0.0465 0.18 0.0245"/>
			</geometry>
			<material name="camera"/>
		</visual>
	</link>

	<link name="wheel_left">
		<visual>
			<origin xyz="0.013 0 0" rpy="0 1.57075 0"/>
			<geometry>
				<cylinder length="0.026" radius="0.05"/>
			</geometry>
			<material name="rubber"/>
		</visual>
	</link>

	<link name="wheel_right">
		<visual>
			<origin xyz="0.013 0 0" rpy="0 1.57075 0"/>
			<geometry>
				<cylinder length="0.026" radius="0.05"/>
			</geometry>
			<material name="rubber"/>
		</visual>
	</link>
	
	
	<!-- joints -->
	<joint name="robot_to_camera_link" type="revolute">
		<parent link="robot"/>
		<child link="camera_link"/>
		<origin xyz="0.00 0.05 0.26" rpy="0.02 0.52 0"/>
		<axis xyz="0 1 0"/>
		<limit lower="-0.785" upper="0.785" effort="0" velocity="0"/>
	</joint>

	<joint name="robot_to_left_wheel" type="continuous">
		<parent link="robot"/>
		<child link="wheel_left"/>
		<origin xyz="0 0.0925 0.05" rpy="0 0 1.57075"/>
		<axis xyz="1 0 0"/>
	</joint>

	<joint name="robot_to_right_wheel" type="continuous">
		<parent link="robot"/>
		<child link="wheel_right"/>
		<origin xyz="0 -0.0925 0.05" rpy="0 0 -1.57075"/>
		<axis xyz="1 0 0"/>
	</joint>
	
	
	<!-- ir-sensors -->
	<link name="ir_front"/>
	<link name="ir_rear"/>
	<link name="ir_left_front"/>
	<link name="ir_left_rear"/>
	<link name="ir_right_front"/>
	<link name="ir_right_rear"/>

	<joint name="robot_to_ir_front" type="fixed">
		<parent link="robot"/>
		<child link="ir_front"/>
		<origin xyz="0.112 0 0.0825" rpy="0 0 0"/>
	</joint>

	<joint name="robot_to_ir_rear" type="fixed">
		<parent link="robot"/>
		<child link="ir_rear"/>
		<origin xyz="-0.112 0 0.0825" rpy="0 0 3.14159"/>
	</joint>

	<joint name="robot_to_ir_left_front" type="fixed">
		<parent link="robot"/>
		<child link="ir_left_front"/>
		<origin xyz="0.082 0.119 0.0825" rpy="0 0 1.57075"/>
	</joint>

	<joint name="robot_to_ir_left_rear" type="fixed">
		<parent link="robot"/>
		<child link="ir_left_rear"/>
		<origin xyz="-0.082 0.119 0.0825" rpy="0 0 1.57075"/>
	</joint>

	<joint name="robot_to_ir_right_front" type="fixed">
		<parent link="robot"/>
		<child link="ir_right_front"/>
		<origin xyz="0.082 -0.119 0.0825" rpy="0 0 -1.57075"/>
	</joint>

	<joint name="robot_to_ir_right_rear" type="fixed">
		<parent link="robot"/>
		<child link="ir_right_rear"/>
		<origin xyz="-0.082 -0.119 0.0825" rpy="0 0 -1.57075"/>
	</joint>
</robot>
